Workbook
Name Slicer_Segment: #N/A
Name Slicer_Ship_Mode: #N/A

Sheet retail_sales_messy_dataset
A1: Order_ID | B1: Order Date | C1: Ship Date | D1: Ship_Mode | E1: customer_id | F1: Customer Name | G1: Segment | H1: Country | I1: City | J1: State | K1: Postal Code | L1: Region | M1: Product_ID | N1: Category | O1: Sub-Category | P1: Product Name | Q1: Sales | R1: Quantity | S1: Discount | T1: Profit
A2: CA-2023-152156 | B2: 11/08/2023 | C2: 11/11/2023 | D2: Second Class | E2: CG-12520 | F2: Claire Gute | G2: Consumer | H2: United States | I2: Henderson | J2: Kentucky | K2: 42420 | L2: South | M2: FUR-BO-10001798 | N2: Furniture | O2: Bookcases | P2: Bush Somerset Collection Bookcase | Q2: 261.96 | R2: 2 | S2: 0 | T2: 41.9136
A3: CA-2023-152156 | B3: 11/08/2023 | C3: 11/11/2023 | D3: Second Class | E3: CG-12520 | F3: Claire Gute | G3: Consumer | H3: United States | I3: Henderson | J3: Kentucky | K3: 42420 | L3: South | M3: FUR-CH-10000454 | N3: Furniture | O3: Chairs | P3: Hon Deluxe Fabric Upholstered Stacking Chairs | Q3: 731.94 | R3: 3 | S3: 0 | T3: 219.582
A4: CA-2023-138688 | B4: 06/12/2023 | D4: Standard Class | E4: DV-13045 | F4: Darrin Van Huff | G4: Corporate | H4: United States | I4: Los Angeles | J4: California | K4: 90036 | L4: West | M4: OFF-LA-10000240 | N4: Office Supplies | O4: Labels | P4: Self-Adhesive Address Labels | Q4: 14.62 | R4: 2 | S4: 0 | T4: 6.8714
A5: US-2023-108966 | B5: 10/11/2023 | C5: 10/18/2023 | D5: Standard Class | E5: SO-20335 | F5: Sean O'Donnell | G5: Consumer | H5: United States | I5: Fort Lauderdale | J5: Florida | K5: 33311 | L5: South | M5: FUR-TA-10000577 | N5: Furniture | O5: Tables | P5: Bretford CR4500 Series Slim Rectangular Table | Q5: 957.5775 | R5: 5 | S5: 0.45 | T5: -383.031
A6: US-2023-108966 | B6: 10/11/2023 | C6: 10/18/2023 | D6: Standard Class | E6: SO-20335 | F6: Sean O'Donnell | G6: Consumer | H6: United States | I6: Fort Lauderdale | J6: Florida | K6: 33311 | L6: South | M6: OFF-ST-10000760 | N6: Office Supplies | O6: Storage | P6: Eldon Fold 'N Roll Cart System | Q6: 22.368 | R6: 2 | S6: 0.2 | T6: 2.5164
A7: CA-2024-115812 | B7: 06/09/2024 | C7: 06/14/2024 | D7: Standard Class | E7: BH-11710 | F7: Brosina Hoffman | G7: Consumer | H7: United States | I7: Los Angeles | J7: California | K7: 90032 | L7: West | M7: FUR-FU-10001487 | N7: Furniture | O7: Furnishings | P7: Eldon Expressions Wood and Plastic Desk Accessories Cherry Wood | Q7: 48.86 | R7: 7 | S7: 0 | T7: 14.1694
A8: CA-2024-115812 | B8: 06/09/2024 | C8: 06/14/2024 | D8: Standard Class | E8: BH-11710 | F8: Brosina Hoffman | G8: Consumer | H8: United States | I8: Los Angeles | J8: California | K8: 90032 | L8: West | M8: OFF-AR-10002833 | N8: Office Supplies | O8: Art | P8: Newell 322 | Q8: 7.28 | R8: 4 | S8: 0 | T8: 1.9656
A9: CA-2024-115812 | B9: 06/09/2024 | C9: 06/14/2024 | D9: Standard Class | E9: BH-11710 | F9: Brosina Hoffman | G9: Consumer | H9: United States | I9: Los Angeles | J9: California | K9: 90032 | L9: West | M9: TEC-PH-10002275 | N9: Technology | O9: Phones | P9: Mitel 5320 IP Phone VoIP phone | Q9: 907.152 | R9: 6 | S9: 0.2 | T9: 90.7152
A10: CA-2023-114412 | B10: 04/15/2023 | C10: 04/20/2023 | D10: Standard Class | E10: AA-10480 | F10: Andrew Allen | G10: Consumer | H10: United States | I10: Concord | J10: North Carolina | K10: 28027 | L10: South | M10: OFF-PA-10002365 | N10: Office Supplies | O10: Paper | P10: Xerox 1967 | Q10: 15.552 | R10: 3 | S10: 0.2 | T10: 5.4432
A11: CA-2023-114412 | B11: 04/15/2023 | C11: 04/20/2023 | D11: Standard Class | E11: AA-10480 | F11: Andrew Allen | G11: Consumer | H11: United States | I11: Concord | J11: North Carolina | K11: 28027 | L11: South | M11: OFF-BI-10003910 | N11: Office Supplies | O11: Binders | P11: Wilson Jones Custom Binder Spines & Labels | Q11: 407.976 | R11: 3 | S11: 0.2 | T11: 132.5922
A12: CA-2023-119823 | B12: 12/08/2023 | C12: 12/12/2023 | D12: Second Class | E12: IM-15070 | F12: Irene Maddox | G12: Consumer | H12: United States | I12: Seattle | J12: Washington | K12: 98103 | L12: West | M12: OFF-AP-10002311 | N12: Office Supplies | O12: Appliances | P12: Belkin 325VA UPS Surge Protector 6 outlets 4 phone lines | Q12: 68.81 | R12: 5 | S12: 0 | T12: 15.3623
A13: CA-2023-119823 | B13: 12/08/2023 | C13: 12/12/2023 | D13: Second Class | E13: IM-15070 | F13: Irene Maddox | G13: Consumer | H13: United States | I13: Seattle | J13: Washington | K13: 98103 | L13: West | M13: FUR-FU-10000260 | N13: Furniture | O13: Furnishings | P13: Ultra Door Holder Bright Silver, Finish | Q13: 33.848 | R13: 8 | S13: 0.2 | T13: 7.645
B14: 12/08/2023 | C14: 12/12/2023 | D14: Second Class | E14: IM-15070 | F14: Irene Maddox | G14: Consumer | H14: United States | I14: Seattle | J14: Washington | K14: 98103 | L14: West | M14: FUR-TA-10001539 | N14: Furniture | O14: Tables | P14: Chromcraft Bull-Nose Wood Oval Conference Tables & Bases | Q14: 1044 | R14: 3 | S14: 0.3 | T14: -277.14
A15: US-2023-150630 | B15: 09/14/2023 | C15: 09/16/2023 | D15: First Class | E15: KM-16375 | F15: Ken Marosh | G15: Consumer | H15: United States | I15: Detroit | J15: Michigan | L15: West | M15: TEC-AC-10003832 | N15: Technology | O15: Accessories | P15: Imation Secure+ Hardware Encrypted USB 2.0 Flash Drive 8GB | Q15: 116.544 | R15: 4 | S15: 0 | T15: 16.3162
A16: US-2023-150630 | B16: 09/14/2023 | C16: 09/16/2023 | D16: First Class | E16: KM-16375 | F16: Ken Marosh | G16: Consumer | H16: United States | I16: Detroit | J16: Michigan | K16: 48205 | L16: West | M16: OFF-BI-10002309 | N16: Office Supplies | O16: Binders | P16: Avery Durable Binders | Q16: 13.48 | R16: 7 | S16: 0 | T16: 4.1026
A17: CA-2024-161389 | B17: 12/05/2024 | C17: 12/10/2024 | D17: Standard Class | E17: ##ERROR## | F17: Sandra Flanagan | G17: Consumer | H17: United States | I17: Philadelphia | J17: Pennsylvania | K17: 19140 | L17: East | M17: FUR-CH-10002774 | N17: Furniture | O17: Chairs | P17: Global Value Mid-Back Manager's Chair Gray | Q17: 213.115 | R17: 3 | S17: 0.45 | T17: -95.904
A18: CA-2024-161389 | B18: 12/05/2024 | C18: 12/10/2024 | D18: Standard Class | E18: SF-20065 | F18: Sandra Flanagan | G18: Consumer | H18: United States | I18: Philadelphia | J18: Pennsylvania | K18: 19140 | L18: East | M18: OFF-FA-10000304 | N18: Office Supplies | O18: Fasteners | P18: Advantus Map Pennant Flags | Q18: 16.5 | R18: 5 | S18: 0.2 | T18: 5.94
A19: CA-2024-143336 | B19: 08/27/2024 | C19: 09/01/2024 | D19: Second Class | E19: PO-19195 | F19: Pete O'Hara | G19: Consumer | H19: United States | I19: Fort Worth | J19: Texas | K19: 76106 | L19: Central | M19: OFF-ST-10004186 | N19: Office Supplies | O19: Storage | P19: Sauder Camden County Barrister Bookcase Planked Cherry Finish | Q19: 440.985 | R19: 3 | S19: 0.35 | T19: -130.07475
A20: US-2023-156909 | B20: 07/16/2023 | C20: 07/18/2023 | D20: First Class | E20: AG-10270 | F20: Alejandro Grove | G20: Consumer | H20: United States | I20: West Jordan | J20: Utah | K20: 84084 | L20: West | M20: TEC-PH-10004093 | N20: Technology | O20: Phones | P20: Cisco SPA 501G IP Phone | Q20: 3083.43 | R20: 7 | S20: 0.4 | T20: -3696.0966
A21: US-2023-156909 | B21: 07/16/2023 | C21: 07/18/2023 | D21: First Class | E21: AG-10270 | F21: Alejandro Grove | G21: Consumer | H21: United States | I21: West Jordan | J21: Utah | K21: 84084 | L21: West | M21: TEC-PH-10004093 | N21: Technology | O21: Phones | P21: Cisco SPA 501G IP Phone | Q21: 3083.43 | R21: 7 | S21: 0.4 | T21: -3696.0966
A22: CA-2024-106320 | B22: 09/25/2024 | C22: 09/30/2024 | D22: Standard Class | E22: ZD-21925 | F22: Zuschuss Donatelli | G22: Consumer | H22: United States | I22: San Francisco | J22: California | K22: 94109 | L22: West | M22: OFF-PA-10003177 | N22: Office Supplies | O22: Paper | P22: Xerox 1952 | Q22: NULL | R22: 4 | S22: 0.8 | T22: NULL
A23: CA-2024-106320 | B23: 09/25/2024 | C23: 09/30/2024 | D23: Standard Class | E23: ZD-21925 | F23: Zuschuss Donatelli | G23: Consumer | H23: United States | I23: San Francisco | J23: California | K23: 94109 | L23: West | M23: TEC-PH-10003645 | N23: Technology | O23: Phones | P23: AT&T CL2909 | Q23: 36.624 | R23: 3 | S23: 0.2 | T23: 7.3248
A24: US-2024-164175 | B24: 04/30/2024 | C24: 05/05/2024 | D24: Standard Class | E24: KB-16585 | F24: Karl Braun | G24: Consumer | H24: United States | I24: Minneapolis | J24: Minnesota | K24: 55407 | L24: Central | M24: FUR-TA-10003034 | N24: Furniture | O24: Tables | P24: Bretford Rectangular Conference Table Tops | Q24: 1096.532 | R24: 2 | S24: 0.4 | T24: -236.2669
A25: US-2024-118983 | B25: 11/22/2024 | C25: 11/26/2024 | D25: Second Class | E25: CC-12370 | F25: Clay Cheatham | G25: Consumer | H25: United States | I25: Detroit | J25: Michigan | K25: 48219 | L25: Central | M25: OFF-AP-10001492 | N25: Office Supplies | O25: Appliances | P25: Acco 7-Outlet Masterpiece Power Center Wiht Phone Line Protection | Q25: 103.92 | R25: 4 | S25: 0.2 | T25: 22.4136
A26: CA-2023-105893 | B26: 11/11/2023 | C26: 11/18/2023 | D26: Standard Class | E26: RH-19495 | F26: Rick Hansen | G26: Consumer | H26: United States | I26: New York City | J26: New York | K26: 10024 | L26: East | M26: TEC-AC-10001998 | N26: Technology | O26: Accessories | P26: Imation USB 2.0 Mini Travel Drive USB Flash Drive | Q26: 21.78 | R26: 3 | S26: 0 | T26: 7.8246
A27: CA-2023-167199 | B27: 12/04/2023 | C27: 12/09/2023 | D27: Second Class | E27: SM-20320 | F27: Sue McLaren | G27: Corporate | H27: United States | I27: San Antonio | J27: Texas | K27: 78212 | L27: Central | M27: OFF-BI-10000474 | N27: Office Supplies | O27: Binders | P27: Cardinal Slant-D Ring Binder Heavy Gauge Vinyl | Q27: 52.776 | R27: 3 | S27: 0 | T27: 19.4994
A28: CA-2023-143259 | B28: 08/09/2023 | C28: 08/13/2023 | D28: Second Class | E28: GM-14650 | F28: Grant Murray | G28: Home Office | H28: United States | I28: Chicago | J28: Illinois | K28: 60623 | L28: Central | M28: OFF-EN-10002986 | N28: Office Supplies | O28: Envelopes | P28: Staples White Wove Envelopes | Q28: NULL | R28: 7 | S28: NULL | T28: -35.532
A29: CA-2023-143259 | B29: 08/09/2023 | C29: 08/13/2023 | D29: Second Class | E29: GM-14650 | F29: Grant Murray | G29: Home Office | H29: United States | I29: Chicago | J29: Illinois | K29: 60623 | L29: Central | M29: FUR-FU-10003799 | N29: Furniture | O29: Furnishings | P29: Tenex Contemporary Contur Chairmats for Low and Medium Pile Carpet 36 x 48 | Q29: 123.552 | R29: 6 | S29: 0.2 | T29: 34.5946
A30: US-2024-150091 | B30: 09/07/2024 | C30: 09/11/2024 | D30: Second Class | E30: DB-13060 | F30: Denny Joy | G30: Consumer | H30: United States | I30: Jacksonville | J30: Florida | K30: 32257 | L30: South | M30: TEC-PH-10004960 | N30: Technology | O30: Phones | P30: Cisco SPA504G 4-Line IP Phone with 2-Port Switch PoE and LCD Display | Q30: 1029.95 | R30: 5 | S30: 0.3 | T30: -514.975
A31: US-2024-150091 | B31: 09/07/2024 | C31: 09/11/2024 | D31: Second Class | E31: DB-13060 | F31: Denny Joy | G31: Consumer | H31: United States | I31: Jacksonville | J31: Florida | K31: 32257 | L31: South | M31: OFF-PA-10000249 | N31: Office Supplies | O31: Paper | P31: Xerox 1999 | Q31: 37.408 | R31: 8 | S31: 0.3 | T31: 12.2246
A32: CA-2024-117590 | B32: 12/08/2024 | C32: 12/10/2024 | D32: First Class | E32: JL-15835 | F32: justin longo | G32: Consumer | H32: United States | I32: Naperville | J32: Illinois | K32: 60540 | L32: Central | M32: FUR-CH-10002960 | N32: Furniture | O32: Chairs | P32: Global Troy Executive Leather Low-Back Tilter | Q32: 489.532 | R32: 4 | S32: 0.45 | T32: -146.8596
A33: CA-2024-117590 | B33: 12/08/2024 | C33: 12/10/2024 | D33: First Class | E33: JL-15835 | F33: Justin Longo | G33: Consumer | H33: United States | I33: Naperville | J33: Illinois | K33: 60540 | L33: Central | M33: TEC-CO-10004722 | N33: Technology | O33: Copiers | P33: Sharp AL-1530CS Digital Copier | Q33: 2799.99 | R33: 3 | S33: 0.4 | T33: -3360
A34: US-2023-146703 | B34: 04/19/2023 | D34: Standard Class | E34: SH-20665 | F34: Shirley Daniels | G34: Consumer | H34: United States | I34: South Bend | J34: Indiana | K34: 46614 | L34: Central | M34: FUR-CH-10002823 | N34: Furniture | O34: Chairs | P34: Global Troy Executive Leather Low-Back Tilter | Q34: 426.588 | R34: 7 | S34: 0.45 | T34: -213.294
A35: US-2023-146703 | B35: 04/19/2023 | C35: 04/26/2023 | D35: Standard Class | E35: SH-20665 | F35: Shirley Daniels | G35: Consumer | H35: United States | I35: South Bend | J35: Indiana | K35: 46614 | L35: Central | M35: OFF-FA-10004123 | N35: Office Supplies | O35: Fasteners | P35: Quartet Cubicle Partition Hangers | Q35: 26.376 | R35: 6 | S35: 0.2 | T35: 7.649
A36: CA-2023-138328 | B36: 06/15/2023 | C36: 06/20/2023 | D36: Standard Class | E36: TC-20980 | F36: Toby Carlisle | G36: Corporate | H36: United States | I36: Portland | J36: Oregon | K36: 97229 | L36: West | M36: FUR-FU-10004848 | N36: Furniture | O36: Furnishings | P36: Eldon Jumbo ProStack Desk Accessories Gray Smoke | Q36: 14.352 | R36: 4 | S36: 0.2 | T36: 4.3056
A37: CA-2024-113258 | B37: 10/24/2024 | C37: 10/31/2024 | D37: Standard Class | E37: DH-13150 | F37: Darrin Hendrix | G37: Consumer | H37: United States | I37: Seattle | J37: Washington | K37: 98115 | L37: West | M37: OFF-AP-10004424 | N37: Office Supplies | O37: Appliances | P37: Fellowes PB500 Electric Punch Plastic Comb Binding Machine with Manual Bind | Q37: 649.784 | R37: 8 | S37: 0.5 | T37: -974.676
A38: CA-2024-113258 | B38: 10/24/2024 | C38: 10/31/2024 | D38: Standard Class | E38: DH-13150 | F38: Darrin Hendrix | G38: Consumer | H38: United States | I38: Seattle | J38: Washington | K38: 98115 | L38: West | M38: TEC-MA-10000822 | N38: Technology | O38: Machines | P38: Lexmark MX611dhe Monochrome Laser Printer | Q38: 2499.99 | R38: 3 | S38: 0.2 | T38: 749.997
A39: CA-2023-135545 | B39: 05/31/2023 | C39: 06/03/2023 | D39: First Class | E39: KT-16555 | F39: Katrina Trentini | G39: Consumer | H39: United States | I39: Richmond | J39: Virginia | K39: 23173 | L39: South | M39: FUR-FU-10004074 | N39: Furniture | O39: Furnishings | P39: Eldon Mobile Utility Cart | Q39: 66.144 | R39: 6 | S39: 0.2 | T39: 12.3619
A40: CA-2024-150965 | B40: 10/05/2024 | C40: 10/10/2024 | D40: Standard Class | E40: LC-17050 | F40: Lena Cacioppo | G40: Consumer | H40: United States | I40: Philadelphia | J40: Pennsylvania | K40: 19120 | L40: East | M40: OFF-BI-10004654 | N40: Office Supplies | O40: Binders | P40: Cardinal Slant-D Ring Binder Heavy Gauge Vinyl | Q40: 18.504 | R40: 3 | S40: 0.2 | T40: 5.5512
...

Sheet Raw_Data
A1: Order_ID | B1: Order Date | C1: Ship Date | D1: Ship_Mode | E1: customer_id | F1: Customer Name | G1: Segment | H1: Country | I1: City | J1: State | K1: Postal Code | L1: Region | M1: Product_ID | N1: Category | O1: Sub-Category | P1: Product Name | Q1: Sales | R1: Quantity | S1: Discount | T1: Profit
A2: CA-2023-152156 | B2: 11/08/2023 | C2: 11/11/2023 | D2: Second Class | E2: CG-12520 | F2: Claire Gute | G2: Consumer | H2: United States | I2: Henderson | J2: Kentucky | K2: 42420 | L2: South | M2: FUR-BO-10001798 | N2: Furniture | O2: Bookcases | P2: Bush Somerset Collection Bookcase | Q2: 261.96 | R2: 2 | S2: 0 | T2: 41.9136
A3: CA-2023-152156 | B3: 11/08/2023 | C3: 11/11/2023 | D3: Second Class | E3: CG-12520 | F3: Claire Gute | G3: Consumer | H3: United States | I3: Henderson | J3: Kentucky | K3: 42420 | L3: South | M3: FUR-CH-10000454 | N3: Furniture | O3: Chairs | P3: Hon Deluxe Fabric Upholstered Stacking Chairs | Q3: 731.94 | R3: 3 | S3: 0 | T3: 219.582
A4: CA-2023-138688 | B4: 06/12/2023 | D4: Standard Class | E4: DV-13045 | F4: Darrin Van Huff | G4: Corporate | H4: United States | I4: Los Angeles | J4: California | K4: 90036 | L4: West | M4: OFF-LA-10000240 | N4: Office Supplies | O4: Labels | P4: Self-Adhesive Address Labels | Q4: 14.62 | R4: 2 | S4: 0 | T4: 6.8714
A5: US-2023-108966 | B5: 10/11/2023 | C5: 10/18/2023 | D5: Standard Class | E5: SO-20335 | F5: Sean O'Donnell | G5: Consumer | H5: United States | I5: Fort Lauderdale | J5: Florida | K5: 33311 | L5: South | M5: FUR-TA-10000577 | N5: Furniture | O5: Tables | P5: Bretford CR4500 Series Slim Rectangular Table | Q5: 957.5775 | R5: 5 | S5: 0.45 | T5: -383.031
A6: US-2023-108966 | B6: 10/11/2023 | C6: 10/18/2023 | D6: Standard Class | E6: SO-20335 | F6: Sean O'Donnell | G6: Consumer | H6: United States | I6: Fort Lauderdale | J6: Florida | K6: 33311 | L6: South | M6: OFF-ST-10000760 | N6: Office Supplies | O6: Storage | P6: Eldon Fold 'N Roll Cart System | Q6: 22.368 | R6: 2 | S6: 0.2 | T6: 2.5164
A7: CA-2024-115812 | B7: 06/09/2024 | C7: 06/14/2024 | D7: Standard Class | E7: BH-11710 | F7: Brosina Hoffman | G7: Consumer | H7: United States | I7: Los Angeles | J7: California | K7: 90032 | L7: West | M7: FUR-FU-10001487 | N7: Furniture | O7: Furnishings | P7: Eldon Expressions Wood and Plastic Desk Accessories Cherry Wood | Q7: 48.86 | R7: 7 | S7: 0 | T7: 14.1694
A8: CA-2024-115812 | B8: 06/09/2024 | C8: 06/14/2024 | D8: Standard Class | E8: BH-11710 | F8: Brosina Hoffman | G8: Consumer | H8: United States | I8: Los Angeles | J8: California | K8: 90032 | L8: West | M8: OFF-AR-10002833 | N8: Office Supplies | O8: Art | P8: Newell 322 | Q8: 7.28 | R8: 4 | S8: 0 | T8: 1.9656
A9: CA-2024-115812 | B9: 06/09/2024 | C9: 06/14/2024 | D9: Standard Class | E9: BH-11710 | F9: Brosina Hoffman | G9: Consumer | H9: United States | I9: Los Angeles | J9: California | K9: 90032 | L9: West | M9: TEC-PH-10002275 | N9: Technology | O9: Phones | P9: Mitel 5320 IP Phone VoIP phone | Q9: 907.152 | R9: 6 | S9: 0.2 | T9: 90.7152
A10: CA-2023-114412 | B10: 04/15/2023 | C10: 04/20/2023 | D10: Standard Class | E10: AA-10480 | F10: Andrew Allen | G10: Consumer | H10: United States | I10: Concord | J10: North Carolina | K10: 28027 | L10: South | M10: OFF-PA-10002365 | N10: Office Supplies | O10: Paper | P10: Xerox 1967 | Q10: 15.552 | R10: 3 | S10: 0.2 | T10: 5.4432
A11: CA-2023-114412 | B11: 04/15/2023 | C11: 04/20/2023 | D11: Standard Class | E11: AA-10480 | F11: Andrew Allen | G11: Consumer | H11: United States | I11: Concord | J11: North Carolina | K11: 28027 | L11: South | M11: OFF-BI-10003910 | N11: Office Supplies | O11: Binders | P11: Wilson Jones Custom Binder Spines & Labels | Q11: 407.976 | R11: 3 | S11: 0.2 | T11: 132.5922
A12: CA-2023-119823 | B12: 12/08/2023 | C12: 12/12/2023 | D12: Second Class | E12: IM-15070 | F12: Irene Maddox | G12: Consumer | H12: United States | I12: Seattle | J12: Washington | K12: 98103 | L12: West | M12: OFF-AP-10002311 | N12: Office Supplies | O12: Appliances | P12: Belkin 325VA UPS Surge Protector 6 outlets 4 phone lines | Q12: 68.81 | R12: 5 | S12: 0 | T12: 15.3623
A13: CA-2023-119823 | B13: 12/08/2023 | C13: 12/12/2023 | D13: Second Class | E13: IM-15070 | F13: Irene Maddox | G13: Consumer | H13: United States | I13: Seattle | J13: Washington | K13: 98103 | L13: West | M13: FUR-FU-10000260 | N13: Furniture | O13: Furnishings | P13: Ultra Door Holder Bright Silver, Finish | Q13: 33.848 | R13: 8 | S13: 0.2 | T13: 7.645
B14: 12/08/2023 | C14: 12/12/2023 | D14: Second Class | E14: IM-15070 | F14: Irene Maddox | G14: Consumer | H14: United States | I14: Seattle | J14: Washington | K14: 98103 | L14: West | M14: FUR-TA-10001539 | N14: Furniture | O14: Tables | P14: Chromcraft Bull-Nose Wood Oval Conference Tables & Bases | Q14: 1044 | R14: 3 | S14: 0.3 | T14: -277.14
A15: US-2023-150630 | B15: 09/14/2023 | C15: 09/16/2023 | D15: First Class | E15: KM-16375 | F15: Ken Marosh | G15: Consumer | H15: United States | I15: Detroit | J15: Michigan | L15: West | M15: TEC-AC-10003832 | N15: Technology | O15: Accessories | P15: Imation Secure+ Hardware Encrypted USB 2.0 Flash Drive 8GB | Q15: 116.544 | R15: 4 | S15: 0 | T15: 16.3162
A16: US-2023-150630 | B16: 09/14/2023 | C16: 09/16/2023 | D16: First Class | E16: KM-16375 | F16: Ken Marosh | G16: Consumer | H16: United States | I16: Detroit | J16: Michigan | K16: 48205 | L16: West | M16: OFF-BI-10002309 | N16: Office Supplies | O16: Binders | P16: Avery Durable Binders | Q16: 13.48 | R16: 7 | S16: 0 | T16: 4.1026
A17: CA-2024-161389 | B17: 12/05/2024 | C17: 12/10/2024 | D17: Standard Class | E17: ##ERROR## | F17: Sandra Flanagan | G17: Consumer | H17: United States | I17: Philadelphia | J17: Pennsylvania | K17: 19140 | L17: East | M17: FUR-CH-10002774 | N17: Furniture | O17: Chairs | P17: Global Value Mid-Back Manager's Chair Gray | Q17: 213.115 | R17: 3 | S17: 0.45 | T17: -95.904
A18: CA-2024-161389 | B18: 12/05/2024 | C18: 12/10/2024 | D18: Standard Class | E18: SF-20065 | F18: Sandra Flanagan | G18: Consumer | H18: United States | I18: Philadelphia | J18: Pennsylvania | K18: 19140 | L18: East | M18: OFF-FA-10000304 | N18: Office Supplies | O18: Fasteners | P18: Advantus Map Pennant Flags | Q18: 16.5 | R18: 5 | S18: 0.2 | T18: 5.94
A19: CA-2024-143336 | B19: 08/27/2024 | C19: 09/01/2024 | D19: Second Class | E19: PO-19195 | F19: Pete O'Hara | G19: Consumer | H19: United States | I19: Fort Worth | J19: Texas | K19: 76106 | L19: Central | M19: OFF-ST-10004186 | N19: Office Supplies | O19: Storage | P19: Sauder Camden County Barrister Bookcase Planked Cherry Finish | Q19: 440.985 | R19: 3 | S19: 0.35 | T19: -130.07475
A20: US-2023-156909 | B20: 07/16/2023 | C20: 07/18/2023 | D20: First Class | E20: AG-10270 | F20: Alejandro Grove | G20: Consumer | H20: United States | I20: West Jordan | J20: Utah | K20: 84084 | L20: West | M20: TEC-PH-10004093 | N20: Technology | O20: Phones | P20: Cisco SPA 501G IP Phone | Q20: 3083.43 | R20: 7 | S20: 0.4 | T20: -3696.0966
A21: US-2023-156909 | B21: 07/16/2023 | C21: 07/18/2023 | D21: First Class | E21: AG-10270 | F21: Alejandro Grove | G21: Consumer | H21: United States | I21: West Jordan | J21: Utah | K21: 84084 | L21: West | M21: TEC-PH-10004093 | N21: Technology | O21: Phones | P21: Cisco SPA 501G IP Phone | Q21: 3083.43 | R21: 7 | S21: 0.4 | T21: -3696.0966
A22: CA-2024-106320 | B22: 09/25/2024 | C22: 09/30/2024 | D22: Standard Class | E22: ZD-21925 | F22: Zuschuss Donatelli | G22: Consumer | H22: United States | I22: San Francisco | J22: California | K22: 94109 | L22: West | M22: OFF-PA-10003177 | N22: Office Supplies | O22: Paper | P22: Xerox 1952 | Q22: NULL | R22: 4 | S22: 0.8 | T22: NULL
A23: CA-2024-106320 | B23: 09/25/2024 | C23: 09/30/2024 | D23: Standard Class | E23: ZD-21925 | F23: Zuschuss Donatelli | G23: Consumer | H23: United States | I23: San Francisco | J23: California | K23: 94109 | L23: West | M23: TEC-PH-10003645 | N23: Technology | O23: Phones | P23: AT&T CL2909 | Q23: 36.624 | R23: 3 | S23: 0.2 | T23: 7.3248
A24: US-2024-164175 | B24: 04/30/2024 | C24: 05/05/2024 | D24: Standard Class | E24: KB-16585 | F24: Karl Braun | G24: Consumer | H24: United States | I24: Minneapolis | J24: Minnesota | K24: 55407 | L24: Central | M24: FUR-TA-10003034 | N24: Furniture | O24: Tables | P24: Bretford Rectangular Conference Table Tops | Q24: 1096.532 | R24: 2 | S24: 0.4 | T24: -236.2669
A25: US-2024-118983 | B25: 11/22/2024 | C25: 11/26/2024 | D25: Second Class | E25: CC-12370 | F25: Clay Cheatham | G25: Consumer | H25: United States | I25: Detroit | J25: Michigan | K25: 48219 | L25: Central | M25: OFF-AP-10001492 | N25: Office Supplies | O25: Appliances | P25: Acco 7-Outlet Masterpiece Power Center Wiht Phone Line Protection | Q25: 103.92 | R25: 4 | S25: 0.2 | T25: 22.4136
A26: CA-2023-105893 | B26: 11/11/2023 | C26: 11/18/2023 | D26: Standard Class | E26: RH-19495 | F26: Rick Hansen | G26: Consumer | H26: United States | I26: New York City | J26: New York | K26: 10024 | L26: East | M26: TEC-AC-10001998 | N26: Technology | O26: Accessories | P26: Imation USB 2.0 Mini Travel Drive USB Flash Drive | Q26: 21.78 | R26: 3 | S26: 0 | T26: 7.8246
A27: CA-2023-167199 | B27: 12/04/2023 | C27: 12/09/2023 | D27: Second Class | E27: SM-20320 | F27: Sue McLaren | G27: Corporate | H27: United States | I27: San Antonio | J27: Texas | K27: 78212 | L27: Central | M27: OFF-BI-10000474 | N27: Office Supplies | O27: Binders | P27: Cardinal Slant-D Ring Binder Heavy Gauge Vinyl | Q27: 52.776 | R27: 3 | S27: 0 | T27: 19.4994
... A33: CA-2024-117590 | B33: 12/08/2024 | C33: 12/10/2024 | D33: First Class | E33: JL-15835 | F33: Justin Longo | G33: Consumer | H33: United States | I33: Naperville | J33: Illinois | K33: 60540 | L33: Central | M33: TEC-CO-10004722 | N33: Technology | O33: Copiers | P33: Sharp AL-1530CS Digital Copier | Q33: 2799.99 | R33: 3 | S33: 0.4 | T33: -3360
A34: US-2023-146703 | B34: 04/19/2023 | D34: Standard Class | E34: SH-20665 | F34: Shirley Daniels | G34: Consumer | H34: United States | I34: South Bend | J34: Indiana | K34: 46614 | L34: Central | M34: FUR-CH-10002823 | N34: Furniture | O34: Chairs | P34: Global Troy Executive Leather Low-Back Tilter | Q34: 426.588 | R34: 7 | S34: 0.45 | T34: -213.294
A35: US-2023-146703 | B35: 04/19/2023 | C35: 04/26/2023 | D35: Standard Class | E35: SH-20665 | F35: Shirley Daniels | G35: Consumer | H35: United States | I35: South Bend | J35: Indiana | K35: 46614 | L35: Central | M35: OFF-FA-10004123 | N35: Office Supplies | O35: Fasteners | P35: Quartet Cubicle Partition Hangers | Q35: 26.376 | R35: 6 | S35: 0.2 | T35: 7.649
A36: CA-2023-138328 | B36: 06/15/2023 | C36: 06/20/2023 | D36: Standard Class | E36: TC-20980 | F36: Toby Carlisle | G36: Corporate | H36: United States | I36: Portland | J36: Oregon | K36: 97229 | L36: West | M36: FUR-FU-10004848 | N36: Furniture | O36: Furnishings | P36: Eldon Jumbo ProStack Desk Accessories Gray Smoke | Q36: 14.352 | R36: 4 | S36: 0.2 | T36: 4.3056
A37: CA-2024-113258 | B37: 10/24/2024 | C37: 10/31/2024 | D37: Standard Class | E37: DH-13150 | F37: Darrin Hendrix | G37: Consumer | H37: United States | I37: Seattle | J37: Washington | K37: 98115 | L37: West | M37: OFF-AP-10004424 | N37: Office Supplies | O37: Appliances | P37: Fellowes PB500 Electric Punch Plastic Comb Binding Machine with Manual Bind | Q37: 649.784 | R37: 8 | S37: 0.5 | T37: -974.676
A38: CA-2024-113258 | B38: 10/24/2024 | C38: 10/31/2024 | D38: Standard Class | E38: DH-13150 | F38: Darrin Hendrix | G38: Consumer | H38: United States | I38: Seattle | J38: Washington | K38: 98115 | L38: West | M38: TEC-MA-10000822 | N38: Technology | O38: Machines | P38: Lexmark MX611dhe Monochrome Laser Printer | Q38: 2499.99 | R38: 3 | S38: 0.2 | T38: 749.997
A39: CA-2023-135545 | B39: 05/31/2023 | C39: 06/03/2023 | D39: First Class | E39: KT-16555 | F39: Katrina Trentini | G39: Consumer | H39: United States | I39: Richmond | J39: Virginia | K39: 23173 | L39: South | M39: FUR-FU-10004074 | N39: Furniture | O39: Furnishings | P39: Eldon Mobile Utility Cart | Q39: 66.144 | R39: 6 | S39: 0.2 | T39: 12.3619
A40: CA-2024-150965 | B40: 10/05/2024 | C40: 10/10/2024 | D40: Standard Class | E40: LC-17050 | F40: Lena Cacioppo | G40: Consumer | H40: United States | I40: Philadelphia | J40: Pennsylvania | K40: 19120 | L40: East | M40: OFF-BI-10004654 | N40: Office Supplies | O40: Binders | P40: Cardinal Slant-D Ring Binder Heavy Gauge Vinyl | Q40: 18.504 | R40: 3 | S40: 0.2 | T40: 5.5512
A41: US-2024-144568 | B41: 04/18/2024 | C41: 04/24/2024 | D41: Standard Class | E41: PE-18865 | F41: Patrick Ellison | G41: Consumer | H41: United States | I41: Sioux Falls | J41: South Dakota | K41: 57104 | L41: Central | M41: TEC-CO-10001047 | N41: Technology | O41: Copiers | P41: Canon PC1080F Personal Copier | Q41: 4199.99 | R41: 5 | S41: 0.4 | T41: -2520
A42: DUPLICATE_ROW | B42: 04/18/2024 | C42: 04/24/2024 | D42: Standard Class | E42: PE-18865 | F42: Patrick Ellison | G42: Consumer | H42: United States | I42: Sioux Falls | J42: South Dakota | K42: 57104 | L42: Central | M42: TEC-CO-10001047 | N42: Technology | O42: Copiers | P42: Canon PC1080F Personal Copier | Q42: 4199.99 | R42: 5 | S42: 0.4 | T42: -2520
A43: CA-2023-105620 | B43: 02/11/2023 | C43: 02/17/2023 | D43: Standard Class | E43: AG-10675 | F43: Anthony Garverick | G43: Consumer | H43: United States | I43: Seattle | J43: Washington | K43: 98103 | L43: West | M43: TEC-PH-10003988 | N43: Technology | O43: Phones | P43: Motorola Talkabout T8500 and T9500 | Q43: 59.99 | R43: 2 | S43: 0.1 | T43: 24.8959
A44: CA-2024-167785 | B44: 05/13/2024 | C44: 05/18/2024 | D44: Standard Class | E44: EC-12145 | F44: Eric Barreto | G44: Consumer | H44: United States | I44: Gary | J44: Indiana | K44: 46402 | L44: Central | M44: OFF-BI-10001525 | N44: Office Supplies | O44: Binders | P44: GBC Prepunched Paper 19-Hole Letter Size | Q44: 38.94 | R44: 3 | S44: 0.2 | T44: 11.682
A45: CA-2024-143982 | B45: 08/27/2024 | C45: 09/01/2024 | D45: Standard Class | E45: TB-21175 | F45: Tracy Blumstein | G45: Consumer | H45: United States | I45: Jacksonville | J45: Florida | K45: 32256 | L45: South | M45: OFF-PA-10001970 | N45: Office Supplies | O45: Paper | P45: Xerox 1916 | Q45: 11.784 | R45: 2 | S45: 0.2 | T45: 4.2426
...

Sheet PT_Sales_by_Category
A3: Row Labels | B3: Sum of Sales
A4: Technology | B4: 22804.916
A5: Furniture | B5: 5508.0005
A6: Office Supplies | B6: 1947.063
A7: Grand Total | B7: 30259.979

Sheet PT_Sales_by_Region_Category
A3: Sum of Sales | B3: Column Labels
A4: Row Labels | B4: Furniture | C4: Office Supplies | D4: Technology | E4: Grand Total
A5: Central | B5: 489.532 | D5: 2799.99 | E5: 3289.522
A6: South | B6: 66.144 | E6: 66.144
A7: West | C7: 13.48 | D7: 6283.404 | E7: 6296.884
A8: Grand Total | B8: 555.676 | C8: 13.48 | D8: 9083.394 | E8: 9652.55

Sheet PT_Profitability_Analysis
A3: Row Labels | B3: Sum of Sales | C3: Sum of Profit | D3: Sum of Profit_Margin
A4: Technology | B4: 22804.916 | C4: -15256.883 | D4: -0.6690173
A5: Phones | B5: 8966.632 | C5: -7631.0211 | D5: -0.85104654
A6: Copiers | B6: 11199.97 | C6: -8400 | D6: -0.75000201
A7: Accessories | B7: 138.324 | C7: 24.1408 | D7: 0.17452358
A8: Machines | B8: 2499.99 | C8: 749.997 | D8: 0.3
A9: Office Supplies | B9: 1947.063 | C9: -882.22665 | D9: -0.45310637
A10: Appliances | B10: 822.514 | C10: -936.9001 | D10: -1.1390689
A11: Storage | B11: 463.353 | C11: -127.55835 | D11: -0.27529411
A12: Art | B12: 7.28 | C12: 1.9656 | D12: 0.27
A13: Fasteners | B13: 42.876 | C13: 13.589 | D13: 0.31693721
A14: Binders | B14: 531.676 | C14: 173.4274 | D14: 0.32619001
A15: Paper | B15: 64.744 | C15: 21.9104 | D15: 0.33841591
A16: Labels | B16: 14.62 | C16: 6.8714 | D16: 0.47
A17: Envelopes | B17: 0 | C17: -35.532 | D17: #DIV/0!
A18: Furniture | B18: 5508.0005 | C18: -1017.9234 | D18: -0.18480815
A19: Tables | B19: 3098.1095 | C19: -896.4379 | D19: -0.28934997
A20: Chairs | B20: 1861.175 | C20: -236.4756 | D20: -0.12705715
A21: Bookcases | B21: 261.96 | C21: 41.9136 | D21: 0.16
A22: Furnishings | B22: 286.756 | C22: 73.0765 | D22: 0.25483861
A23: Grand Total | B23: 30259.979 | C23: -17157.033 | D23: -0.56698761

Sheet Action_Plan
A2: Prioridad | B2: Área | C2: Acción Recomendada
A3: CRÍTICA | B3: Technology | C3: DETENER VENTAS de Phones inmediatamente y renegociar contratos de Copiers.
A4: ALTA | B4: Furniture | C4: Revisar estrategia de precios en Mesas y Sillas; potenciar marketing en Libreros (único rentable).
A5: MEDIA | B5: Region | C5: Cerrar o fusionar la región East ($270 total) con Central para reducir costos operativos.
A6: OPERATIVA | B6: Product Mix | C6: Eliminar Appliances (-113% margen) y promover Office Supplies (Papel, Sujetadores) por su alta rentabilidad.
A7: SIGUIENTE | B7: Auditoría | C7: Realizar desglose de costos de proveedores y auditar políticas de descuento en el último trimestre.

Sheet Dashboards
B2: RETAIL PERFORMANCE ANALYSIS · Business Intelligence Dashboard
B4: FY 2023–2024 · United States Market · 46 Transactions · 3 Categories · 4 Regions
B6: 💰 Total Revenue $30,260 Revenue across all categories | G6: 📉 Total Profit ($17,157) Net loss — action required | K6: ⚠️ Profit Margin -56.7% Driven by Phones & Copiers
B8: SALES BY CATEGORY | H8: PROFITABILITY BY SUB-CATEGORY
B9: Category | C9: Sales ($) | D9: Profit ($) | H9: Sub-Category | I9: Profit ($)
B10: Technology | C10: 22804.92 | D10: -15256.88 | H10: Phones | I10: -7631.02
B11: Furniture | C11: 5508 | D11: -1017.92 | H11: Copiers | I11: -8400
B12: Office Supplies | C12: 1947.06 | D12: -882.23 | H12: Appliances | I12: -936.9
H13: Tables | I13: -896.44
H14: Chairs | I14: -236.48
H15: Storage | I15: -127.56
H16: Machines | I16: 749.997
H17: Binders | I17: 173.43
H18: Paper | I18: 21.91
H19: Fasteners | I19: 13.59
B26: MONTHLY SALES TREND · FY 2023–2024
B27: Month | C27: Sales ($)
B28: Feb 2023 | C28: 59.99
B29: Apr 2023 | C29: 876.49
B30: May 2023 | C30: 66.14
B31: Jun 2023 | C31: 28.97
B32: Jul 2023 | C32: 6166.86
B33: Aug 2023 | C33: 123.55
B34: Sep 2023 | C34: 130.02
B35: Oct 2023 | C35: 979.95
B36: Nov 2023 | C36: 1015.68
B37: Dec 2023 | C37: 1199.43
B38: Apr 2024 | C38: 9496.51
B39: May 2024 | C39: 38.94
... B45: Dec 2024 | C45: 3519.14
B47: STRATEGIC ACTION PLAN
B48: Priority | D48: Area | F48: Recommended Action
B49: 🔴 CRITICAL | D49: Technology | F49: Stop Phones sales immediately · Renegotiate Copiers contracts
B50: 🟠 HIGH | D50: Furniture | F50: Review pricing on Tables & Chairs · Promote Bookcases (only profitable)
B51: 🟡 MEDIUM | D51: Region | F51: Merge East region ($270 total) with Central to cut operating costs
B52: 🔵 OPERATIONAL | D52: Product Mix | F52: Eliminate Appliances (-113% margin) · Promote Paper & Fasteners
B53: ⚪ NEXT STEP | D53: Audit | F53: Full supplier cost breakdown · Audit discount policies Q4
B55: Data Analyst Portfolio · Hugo Ernesto Aguilar Gallardo · github.com/Ernestoaguiga · Data that speaks. Visuals that sell. Business that grows.

Sheet Practice_formulas
A1: Order_ID | B1: Category (VLOOKUP) | C1: Sale (VLOOKUP) | D1: IFERROR | E1: INDEX.MATCH
A2: CA-2023-152156 | B2: =VLOOKUP(A2, 'Raw_Data'!$A$2:$O$50, 14, 0) -> Furniture | C2: =VLOOKUP(A2, 'Raw_Data'!$A$2:$U$50, 17, 0) -> 261.96 | D2: =IFERROR(VLOOKUP(A2,Raw_Data[],14,0),"Not Found") -> Furniture | E2: =INDEX('Raw_Data'!$N$2:$N$50, MATCH(A2, 'Raw_Data'!$A$2:$A$50, 0)) -> Furniture | F2: =INDEX('Raw_Data'!$A$1:$T$50, MATCH("Order_ID", 'Raw_Data'!$A$1:$A$50, 0), MATCH("Sales", 'Raw_Data'!$1:$1, 0)) -> Sales | G2: =IFERROR(INDEX('Raw_Data'!$N$2:$N$50, MATCH(A2, 'Raw_Data'!$A$2:$A$50, 0)), "No encontrado") -> Furniture
A3: US-2023-108966 | B3: =VLOOKUP(A3, 'Raw_Data'!$A$2:$O$50, 14, 0) -> Furniture | C3: =VLOOKUP(A3, 'Raw_Data'!$A$2:$U$50, 17, 0) -> 957.5775 | D3: =IFERROR(VLOOKUP(A3,Raw_Data[],14,0),"Not Found") -> Furniture | E3: =INDEX('Raw_Data'!$N$2:$N$50, MATCH(A3, 'Raw_Data'!$A$2:$A$50, 0)) -> Furniture | F3: =INDEX('Raw_Data'!$A$1:$T$50, MATCH("Order_ID", 'Raw_Data'!$A$1:$A$50, 0), MATCH("Sales", 'Raw_Data'!$1:$1, 0)) -> Sales | G3: =IFERROR(INDEX('Raw_Data'!$N$2:$N$50, MATCH(A3, 'Raw_Data'!$A$2:$A$50, 0)), "No encontrado") -> Furniture
A4: CA-2024-115812 | B4: =VLOOKUP(A4, 'Raw_Data'!$A$2:$O$50, 14, 0) -> Furniture | C4: =VLOOKUP(A4, 'Raw_Data'!$A$2:$U$50, 17, 0) -> 48.86 | D4: =IFERROR(VLOOKUP(A4,Raw_Data[],14,0),"Not Found") -> Furniture | E4: =INDEX('Raw_Data'!$N$2:$N$50, MATCH(A4, 'Raw_Data'!$A$2:$A$50, 0)) -> Furniture | F4: =INDEX('Raw_Data'!$A$1:$T$50, MATCH("Order_ID", 'Raw_Data'!$A$1:$A$50, 0), MATCH("Sales", 'Raw_Data'!$1:$1, 0)) -> Sales | G4: =IFERROR(INDEX('Raw_Data'!$N$2:$N$50, MATCH(A4, 'Raw_Data'!$A$2:$A$50, 0)), "No encontrado") -> Furniture
A5: CA-2023-114412 | B5: =VLOOKUP(A5, 'Raw_Data'!$A$2:$O$50, 14, 0) -> Office Supplies | C5: =VLOOKUP(A5, 'Raw_Data'!$A$2:$U$50, 17, 0) -> 15.552 | D5: =IFERROR(VLOOKUP(A5,Raw_Data[],14,0),"Not Found") -> Office Supplies | E5: =INDEX('Raw_Data'!$N$2:$N$50, MATCH(A5, 'Raw_Data'!$A$2:$A$50, 0)) -> Office Supplies | F5: =INDEX('Raw_Data'!$A$1:$T$50, MATCH("Order_ID", 'Raw_Data'!$A$1:$A$50, 0), MATCH("Sales", 'Raw_Data'!$1:$1, 0)) -> Sales | G5: =IFERROR(INDEX('Raw_Data'!$N$2:$N$50, MATCH(A5, 'Raw_Data'!$A$2:$A$50, 0)), "No encontrado") -> Office Supplies
